<?xml version="1.0" ?>

<!-- =========================================================================================================================================-->
<!-- | 					Team Anveshak, CFI, IIT Madras                                                                  -->
<!-- |                     This is the official Robot Description of Team Anveshak's Galileo Manipulator                                      -->
<!-- | The Manipulator is attached with a 2 finger gripper from Robotiq and has an Intel Realsense Depth Camera in Eye-in-hand Configuration  -->
<!-- ======================================================================================================================================== -->

<robot name="galileo_arm" xmlns:xacro="http://www.ros.org/wiki/xacro">

<xacro:include filename="$(find arm_description)/urdf/materials.xacro" />
<xacro:include filename="$(find arm_description)/urdf/arm.trans" />
<xacro:include filename="$(find arm_description)/urdf/arm.gazebo" />
<!--xacro:include filename="$(find robotiq_2f_85_gripper_visualization)/urdf/robotiq_arg2f_85_model.xacro"/-->

<!-- manipulator links -->

<!--link name="world"></link-->

<link name="base_link">
   <inertial>
    <origin xyz="-0.002716977299773592 1.9808719046125134e-13 -0.002500000000000375" rpy="0 0 0"/>
    <mass value="150"/>
    <inertia ixx="10" iyy="10" izz="15" ixy="0" iyz="0.0" ixz="-10"/>
  </inertial>
  <visual>
    <origin xyz="0 0 0" rpy="0 0 0"/>
    <geometry>
      <mesh filename="package://arm_description/meshes/base_link.stl" scale="0.001 0.001 0.001"/>
    </geometry>
    <material name="steel_satin"/>
  </visual>
  <collision>
    <origin xyz="0 0 0" rpy="0 0 0"/>
    <geometry>
      <mesh filename="package://arm_description/meshes/base_link.stl" scale="0.001 0.001 0.001"/>
    </geometry>
  </collision>
</link>

<link name="forearm_link">
  <inertial>
    <origin xyz="-0.1170701569437167 0.05258495071306836 0.24677061589144064" rpy="0 0 0"/>
    <mass value="1.5"/>
    <inertia ixx="0.20432" iyy="0.24363" izz="0.5288" ixy="0.456" iyz="-0.1594" ixz="0.9271"/>
  </inertial>
  <visual>
    <origin xyz="0.0375 -0.034 -0.0425" rpy="0 0 0"/>
    <geometry>
      <mesh filename="package://arm_description/meshes/link1_1.stl" scale="0.001 0.001 0.001"/>
    </geometry>
    <material name="default"/>
  </visual>
  <collision>
    <origin xyz="0.0375 -0.034 -0.0425" rpy="0 0 0"/>
    <geometry>
      <mesh filename="package://arm_description/meshes/link1_1.stl" scale="0.001 0.001 0.001"/>
    </geometry>
  </collision>
</link>

<link name="wrist_1_link">
  <inertial>
    <origin xyz="0.0912652794492105 -0.04755997480137449 0.15715086928559246" rpy="0 0 0"/>
    <mass value="1"/>
    <inertia ixx="0.52" iyy="0.1219" izz="0.3285" ixy="0.233" iyz="0.401" ixz="-0.5183"/>
  </inertial>
  <visual>
    <origin xyz="0.235094 -0.046 -0.459007" rpy="0 0 0"/>
    <geometry>
      <mesh filename="package://arm_description/meshes/link2_1.stl" scale="0.001 0.001 0.001"/>
    </geometry>
    <material name="default"/>
  </visual>
  <collision>
    <origin xyz="0.235094 -0.046 -0.459007" rpy="0 0 0"/>
    <geometry>
      <mesh filename="package://arm_description/meshes/link2_1.stl" scale="0.001 0.001 0.001"/>
    </geometry>
  </collision>
</link>

<link name="wrist_2_link">
  <inertial>
    <origin xyz="0.012554620120246197 2.599084142351771e-13 0.021619020423368274" rpy="0 0 0"/>
    <mass value="0.3"/>
    <inertia ixx="0.05" iyy="0.05" izz="0.03" ixy="0.0" iyz="0.0" ixz="0.1"/>
  </inertial>
  <visual>
    <origin xyz="-0.016007 0.0075 -0.891382" rpy="0 0 0"/>
    <geometry>
      <mesh filename="package://arm_description/meshes/tip_1.stl" scale="0.001 0.001 0.001"/>
    </geometry>
    <material name="steel_satin"/>
  </visual>
  <collision>
    <origin xyz="-0.016007 0.0075 -0.891382" rpy="0 0 0"/>
    <geometry>
      <mesh filename="package://arm_description/meshes/tip_1.stl" scale="0.001 0.001 0.001"/>
    </geometry>
  </collision>
</link>

<link name="shoulder_link">
  <inertial>
    <origin xyz="-0.00379841512801708 -4.326319553927361e-16 0.05885490789415437" rpy="0 0 0"/>
    <mass value="1"/>
    <inertia ixx="0.5" iyy="0.639" izz="0.3" ixy="0.0" iyz="-0.0" ixz="0.01"/>
  </inertial>
  <visual>
    <origin xyz="0.0 -0.0 0.0" rpy="0 0 0"/>
    <geometry>
      <mesh filename="package://arm_description/meshes/shoulder_1.stl" scale="0.001 0.001 0.001"/>
    </geometry>
    <material name="default"/>
  </visual>
  <collision>
    <origin xyz="0.0 -0.0 0.0" rpy="0 0 0"/>
    <geometry>
      <mesh filename="package://arm_description/meshes/shoulder_1.stl" scale="0.001 0.001 0.001"/>
    </geometry>
  </collision>
</link>

<link name="tool_tip"></link>

<!-- gripper -->

<!--joint name="gripper_joint" type="fixed">
    <axis xyz="0 0 0" />
    <origin xyz="0 0 0" rpy="0 1.57 0"/>
    <parent link="tool_tip"/>
    <child link="robotiq_arg2f_base_link"/>
</joint-->


<!--intel realsense camera -->

<!--joint name="intelrealsense" type="fixed">
    <axis xyz="0 0 0" />
    <origin xyz="-0.07 0.01 0.02" rpy="0 -1.046 0"/>
    <parent link="wrist_2_link"/>
    <child link="camera_link"/>
</joint>
  
<link name="camera_link">
    <collision>
      <origin xyz="0.02 0 0" rpy="0 0 0"/>
      <geometry>
        <box size="0.001 0.001 0.001"/>
      </geometry>
    </collision>

    <visual>
      <origin xyz="0 0 0" rpy="1.5707 0 1.5707"/>
      <geometry>
         <mesh filename="package://arm_description/meshes/NAVRS.STL" />
      </geometry>
    </visual>

    <inertial>
      <mass value="1e-5" />
      <origin xyz="0 0 0" rpy="0 0 0"/>
      <inertia ixx="0" ixy="0" ixz="0" iyy="0" iyz="0" izz="0" />
    </inertial>
</link>

<joint name="camera_optical_joint" type="fixed">
    <origin xyz="0 0 0" rpy="${-pi/2} 0 ${-pi/2}"/>
    <parent link="camera_link"/>
    <child link="camera_rgb_frame"/>
</joint>

<link name="camera_rgb_frame"></link>

<joint name="camera_depth_joint" type="fixed">
    <origin xyz="0 0 0" rpy="${-pi/2} 0 ${-pi/2}"/>
    <parent link="camera_link"/>
    <child link="camera_depth_frame"/>
</joint>

<link name="camera_depth_frame"></link-->

<!-- manipulator joints -->

<!--joint name="world_joint" type="fixed">
   <parent link="world"/>
   <child link="base_link"/>
</joint-->

<joint name="shoulder_pan_joint" type="continuous">
  <origin xyz="0.0 0.0 0.0" rpy="0 0 0"/>
  <parent link="base_link"/>
  <child link="shoulder_link"/>
  <axis xyz="-0.0 0.0 1.0"/>
</joint>

<joint name="shoulder_lift_joint" type="continuous">
  <origin xyz="-0.0375 0.034 0.0425" rpy="0 0 0"/>
  <parent link="shoulder_link"/>
  <child link="forearm_link"/>
  <axis xyz="-0.0 1.0 -0.0"/>
  
</joint>

<joint name="elbow_joint" type="continuous">
  <origin xyz="-0.197594 0.012 0.416507" rpy="0 0 0"/>
  <parent link="forearm_link"/>
  <child link="wrist_1_link"/>
  <axis xyz="0.0 -1.0 0.0"/>
 
</joint>

<joint name="wrist_joint" type="revolute">
  <origin xyz="0.251101 -0.0535 0.432375" rpy="0 0 0"/>
  <parent link="wrist_1_link"/>
  <child link="wrist_2_link"/>
  <axis xyz="-0.0 1.0 0.0"/>
  <limit upper="1.22173" lower="-1.22173" effort="100" velocity="100"/>
</joint>

<joint name="ee_joint" type="continuous">
  <origin xyz="0.0 0.0 0.0" rpy="0 -1 0"/>
  <parent link="wrist_2_link"/>
  <child link="tool_tip"/>
  <axis xyz="-1.0 0.0 0.0"/>
  
</joint>



</robot>
